#VRML_SIM R2023b utf8
# license: Apache License 2.0
# license url: http://www.apache.org/licenses/LICENSE-2.0
# This is a proto file for Webots for the MotomanMh180120
# Extracted from: /home/srb-jarvis/ros2_ws/ws_motomanmh180/motoman_mh180/src/mh180_simulation/urdf/motoman_mh180.urdf

PROTO MotomanMh180120 [
  field  SFVec3f     translation     0 0 0
  field  SFRotation  rotation        0 0 1 0
  field  SFString    name            "MotomanMh180120"  # Is `Robot.name`.
  field  SFString    controller      "void"             # Is `Robot.controller`.
  field  MFString    controllerArgs  []                 # Is `Robot.controllerArgs`.
  field  SFString    customData      ""                 # Is `Robot.customData`.
  field  SFBool      supervisor      FALSE              # Is `Robot.supervisor`.
  field  SFBool      synchronization TRUE               # Is `Robot.synchronization`.
  field  SFBool      selfCollision   FALSE              # Is `Robot.selfCollision`.
]
{
  Robot {
    translation IS translation
    rotation IS rotation
    controller IS controller
    controllerArgs IS controllerArgs
    customData IS customData
    supervisor IS supervisor
    synchronization IS synchronization
    selfCollision IS selfCollision
    children [
      Shape {
        appearance DEF blue PBRAppearance {
          baseColor 0.000000 0.000000 1.000000
          roughness 1.000000
          metalness 0
        }
        geometry DEF base_link Mesh {
          url "../meshes/mh180/visual/base_link.stl"
        }
      }
      HingeJoint {
        jointParameters HingeJointParameters {
          axis 0.000000 0.000000 1.000000
          anchor 0.000000 0.000000 0.650000
        }
        device [
          RotationalMotor {
            name "group_1/joint_1"
            maxVelocity 2.181661564992912
            minPosition -3.141592653589793
            maxPosition 3.141592653589793
            maxTorque 10000.0
          }
          PositionSensor {
            name "group_1/joint_1_sensor"
          }
        ]
        endPoint Solid {
          translation 0.000000 0.000000 0.650000
          children [
            Shape {
              appearance USE blue
              geometry DEF link_s Mesh {
                url "../meshes/mh180/visual/link_s.stl"
              }
            }
            HingeJoint {
              jointParameters HingeJointParameters {
                axis 0.000000 1.000000 0.000000
                anchor 0.325000 0.000000 0.000000
              }
              device [
                RotationalMotor {
                  name "group_1/joint_2"
                  maxVelocity 2.007128639793479
                  minPosition -1.0471975511965976
                  maxPosition 1.3264502315156905
                  maxTorque 10000.0
                }
                PositionSensor {
                  name "group_1/joint_2_sensor"
                }
              ]
              endPoint Solid {
                translation 0.325000 0.000000 0.000000
                children [
                  Shape {
                    appearance USE blue
                    geometry DEF link_l Mesh {
                      url "../meshes/mh180/visual/link_l.stl"
                    }
                  }
                  HingeJoint {
                    jointParameters HingeJointParameters {
                      axis 0.000000 -1.000000 0.000000
                      anchor 0.000000 0.000000 1.150000
                    }
                    device [
                      RotationalMotor {
                        name "group_1/joint_3"
                        maxVelocity 2.181661564992912
                        minPosition -1.4835298641951802
                        maxPosition 1.5707963267948966
                        maxTorque 5000.0
                      }
                      PositionSensor {
                        name "group_1/joint_3_sensor"
                      }
                    ]
                    endPoint Solid {
                      translation 0.000000 0.000000 1.150000
                      children [
                        Shape {
                          appearance USE blue
                          geometry DEF link_u Mesh {
                            url "../meshes/mh180_120/visual/link_u.stl"
                          }
                        }
                        HingeJoint {
                          jointParameters HingeJointParameters {
                            axis -1.000000 0.000000 0.000000
                            anchor 0.000000 0.000000 0.300000
                          }
                          device [
                            RotationalMotor {
                              name "group_1/joint_4"
                              maxVelocity 3.1764992386296798
                              minPosition -6.283185307179586
                              maxPosition 6.283185307179586
                              maxTorque 5000.0
                            }
                            PositionSensor {
                              name "group_1/joint_4_sensor"
                            }
                          ]
                          endPoint Solid {
                            translation 0.000000 0.000000 0.300000
                            children [
                              Shape {
                                appearance USE blue
                                geometry DEF link_r Mesh {
                                  url "../meshes/mh180_120/visual/link_r.stl"
                                }
                              }
                              HingeJoint {
                                jointParameters HingeJointParameters {
                                  axis 0.000000 -1.000000 0.000000
                                  anchor 1.590000 0.000000 0.000000
                                }
                                device [
                                  RotationalMotor {
                                    name "group_1/joint_5"
                                    maxVelocity 3.0543261909900767
                                    minPosition -2.2689280275926285
                                    maxPosition 2.2689280275926285
                                    maxTorque 2500.0
                                  }
                                  PositionSensor {
                                    name "group_1/joint_5_sensor"
                                  }
                                ]
                                endPoint Solid {
                                  translation 1.590000 0.000000 0.000000
                                  children [
                                    Shape {
                                      appearance USE blue
                                      geometry DEF link_b Mesh {
                                        url "../meshes/mh180/visual/link_b.stl"
                                      }
                                    }
                                    HingeJoint {
                                      jointParameters HingeJointParameters {
                                        axis -1.000000 0.000000 0.000000
                                        anchor 0.225000 0.000000 0.000000
                                      }
                                      device [
                                        RotationalMotor {
                                          name "group_1/joint_6"
                                          maxVelocity 4.625122517784973
                                          minPosition -6.283185307179586
                                          maxPosition 6.283185307179586
                                          maxTorque 2500.0
                                        }
                                        PositionSensor {
                                          name "group_1/joint_6_sensor"
                                        }
                                      ]
                                      endPoint Solid {
                                        translation 0.225000 0.000000 0.000000
                                        children [
                                          Shape {
                                            appearance DEF black PBRAppearance {
                                              baseColor 0.000000 0.000000 0.000000
                                              roughness 1.000000
                                              metalness 0
                                            }
                                            geometry DEF link_t Mesh {
                                              url "../meshes/mh180/visual/link_t.stl"
                                            }
                                          }
                                          Solid {
                                            children [
                                              Transform {
                                                scale 0.001 0.001 0.001
                                                translation -0.012 -0.002 0.04
                                                rotation 0 0.0309851 0.99952 3.14159
                                                children [
                                                  Shape {
                                                    appearance DEF black PBRAppearance {
                                                      baseColor 0.000000 0.000000 0.000000
                                                      roughness 1.000000
                                                      metalness 0
                                                    }
                                                    geometry DEF heusch_end_effector Mesh {
                                                      url "../meshes/end_effector/heusch_end_effector.dae"
                                                    }
                                                  }
                                                ]
                                              }
                                            ]
                                            name "roller"
                                          }
                                        ]
                                        name "link_t"
                                        boundingObject USE link_t
                                        #physics Physics {
                                        #}
                                      }
                                    }
                                  ]
                                  name "link_b"
                                  boundingObject USE link_b
                                  #physics Physics {
                                  #}
                                }
                              }
                            ]
                            name "link_r"
                            boundingObject USE link_r
                            #physics Physics {
                            #}
                          }
                        }
                      ]
                      name "link_u"
                      boundingObject USE link_u
                      #physics Physics {
                      #}
                    }
                  }
                ]
                name "link_l"
                boundingObject USE link_l
                #physics Physics {
                #}
              }
            }
          ]
          name "link_s"
          boundingObject USE link_s
          #physics Physics {
          #}
        }
      }
    ]
    name IS name
    boundingObject USE base_link
    #physics Physics {
    #}
  }
}
